Workbook

Sheet CENA FIN DE AÑO 2024
F2: LLAMADO TELEFONICO | G2: 1
F3: REUNION PRESENCIAL | G3: 2
I4: JUNIO | AM4: JULIO | BR4: NOVIEMBRE | CW4: DICIEMBRE | EA4: ENERO | FF4: FEBRERO
A5: 45639 | B5: CONFIRMADOS | C5: TOTAL A INVITAR | D5: SIN RESPONDER | E5: N° | F5: Nombre Productor | G5: Compañía | H5: Correos Electrónicos | I5: 1 | J5: 2 | K5: 3 | L5: 4 | M5: 5 | N5: 6 | O5: 7 | P5: 8 | Q5: 9 | R5: 10 | S5: 11 | T5: 12 | U5: 13 | V5: 14 | W5: 15 | X5: 16 | Y5: 17 | Z5: 18 | AA5: 19 | AB5: 20 | AC5: 21 | AD5: 22 | AE5: 23 | AF5: 24 | AG5: 25 | AH5: 26 | AI5: 27 | AJ5: 28 | AK5: 29 | AL5: 30 | AM5: 1 | AN5: 2 | AO5: 3 | AP5: 4 | AQ5: 5 | AR5: 6 | AS5: 7 | AT5: 8 | AU5: 9 | AV5: 10 | AW5: 11 | AX5: 12 | AY5: 13 | AZ5: 14 | BA5: 15 | BB5: 16 | BC5: 17 | BD5: 18 | BE5: 19 | BF5: 20 | BG5: 21 | BH5: 22 | BI5: 23 | BJ5: 24 | BK5: 25 | BL5: 26 | BM5: 27 | BN5: 28 | BO5: 29 | BP5: 30 | BQ5: 31 | BR5: 1 | BS5: 2 | BT5: 3 | BU5: 4 | BV5: 5 | BW5: 6 | BX5: 7 | BY5: 8 | BZ5: 9 | CA5: 10 | CB5: 11 | CC5: 12 | CD5: 13 | CE5: 14 | CF5: 15 | CG5: 16 | CH5: 17 | CI5: 18 | CJ5: 19 | CK5: 20 | CL5: 21 | CM5: 22 | CN5: 23 | CO5: 24 | CP5: 25 | CQ5: 26 | CR5: 27 | CS5: 28 | CT5: 29 | CU5: 30 | CV5: 31 | CW5: 1 | CX5: 2 | CY5: 3 | CZ5: 4 | DA5: 5 | DB5: 6 | DC5: 7 | DD5: 8 | DE5: 9 | DF5: 10 | DG5: 11 | DH5: 12 | DI5: 13 | DJ5: 14 | DK5: 15 | DL5: 16 | DM5: 17 | DN5: 18 | DO5: 19 | DP5: 20 | DQ5: 21 | DR5: 22 | DS5: 23 | DT5: 24 | DU5: 25 | DV5: 26 | DW5: 27 | DX5: 28 | DY5: 29 | DZ5: 30 | EA5: 1 | EB5: 2 | EC5: 3 | ED5: 4 | EE5: 5 | EF5: 6 | EG5: 7 | EH5: 8 | EI5: 9 | EJ5: 10 | EK5: 11 | EL5: 12 | EM5: 13 | EN5: 14 | EO5: 15 | EP5: 16 | EQ5: 17 | ER5: 18 | ES5: 19 | ET5: 20 | EU5: 21 | EV5: 22 | EW5: 23 | EX5: 24 | EY5: 25 | EZ5: 26 | FA5: 27 | FB5: 28 | FC5: 29 | FD5: 30 | FE5: 31 | FF5: 1 | FG5: 2 | FH5: 3 | FI5: 4 | FJ5: 5 | FK5: 6 | FL5: 7 | FM5: 8 | FN5: 9 | FO5: 10 | FP5: 11 | FQ5: 12 | FR5: 13 | FS5: 14 | FT5: 15 | FU5: 16 | FV5: 17 | FW5: 18 | FX5: 19 | FY5: 20 | FZ5: 21 | GA5: 22 | GB5: 23 | GC5: 24 | GD5: 25 | GE5: 26 | GF5: 27 | GG5: 28 | GH5: 29 | GI5: 30 | GJ5: 31
B6: 1 | C6: 1 | E6: 1 | F6: Agrelo, Gonzalo | G6: SANCOR | H6: gagrelo@pennesi.com.ar | N6: X | U6: x | AN6: 1 | BW6: 1 | BY6: 1 | CB6: 1 | CJ6: 1 | CL6: 1 | CQ6: 1 | CS6: 1 | CT6: 1 | CU6: 1 | CX6: 1 | CZ6: 1 | DA6: 1 | DE6: 1 | DL6: 1 | DP6: 1 | EF6: 1 | FA6: 1 | FR6: 1
B7: 1 | C7: 1 | E7: 2 | F7: Aguirre, Mauricio | G7: MAPFRE | H7: segurosaguirre@hotmail.com | N7: X | U7: 1 | AN7: 1 | BW7: 1 | BY7: 1 | CB7: 1 | CC7: 2 | CD7: 1 | CJ7: 1 | CK7: 1 | DA7: 1 | DE7: 1 | DP7: 1 | EF7: 1 | FA7: 1 | FB7: 1 | FJ7: 1 | FP7: 1
A8: si | B8: 1 | C8: 1 | E8: 3 | F8: Alcaniz, Angel David | G8: SMG | H8: daalcanis@gmail.com | N8: X | U8: 1 | BW8: 1 | CB8: 1 | CD8: 1 | CL8: 1 | CS8: 1 | CX8: 1 | DA8: 1 | DG8: 1 | DL8: 1 | FL8: 1
A9: ? | E9: 4 | F9: Antún, Maria Elena | H9: mariaelena64@live.com.ar | O9: X | CB9: 1 | CS9: 1
A10: si | B10: 1 | C10: 1 | E10: 5 | F10: Barbero, María Fernanda | G10: SAN CRISTOBAL | H10: infodos.jcorg@gmail.com | O10: X | AG10: 1 | AN10: 1 | CD10: 1 | DE10: 1 | FC10: 1 | FK10: 1 | FP10: 1
A11: si | B11: 1 | C11: 1 | E11: 6 | F11: BARDON MARIA INES | H11: mariainesbardon@gmail.com | P11: X | S11: x | U11: 1 | AN11: 1 | CX11: 1 | CY11: 1 | DG11: 1 | DK11: 1 | DL11: 1
A12: si | B12: 1 | C12: 1 | E12: 7 | F12: BARRERA JOSE LUIS | G12: MAPFRE | H12: barrera_joseluis@yahoo.com | U12: 1 | AN12: 1
A13: no sabe | B13: 1 | C13: 1 | E13: 8 | F13: Bassanese, Virginia | H13: vbassanese@jcorg.com.ar | Z13: 1 | CS13: 1
A14: si | B14: 1 | C14: 1 | E14: 9 | F14: Ale Bergas | G14: SMG RIVADAVIA | H14: alejandrobergas@gmail.com | N14: X | O14: X | R14: x | AF14: 1 | AM14: 2 | BW14: 2 | BY14: 2 | CB14: 1 | CX14: 1 | DG14: 1
C15: 1 | E15: 10 | F15: Bustos López, David Renato | CJ15: 1 | DG15: 1
A16: si | B16: 1 | C16: 1 | E16: 11 | F16: CAPITANI HORACIO ANIBAL | G16: SAN CRISTOBAL | H16: hcapitani16@gmail.com | N16: X | O16: X | T16: x | U16: 1 | W16: 2 | Z16: 2 | AF16: 1 | AG16: 2 | AM16: 2 | AO16: 2 | CB16: 2 | CD16: 1 | CK16: 2 | CL16: 1 | DG16: 1 | EF16: 1 | EG16: 2 | FF16: 1 | FR16: 1
A17: no | C17: 1 | E17: 12 | F17: Chiarolla, María Cecilia | G17: SANCOR | H17: cecichiarolla@hotmail.com | O17: X | U17: 1 | AG17: 1 | AJ17: 2 | BY17: 1 | CD17: 1 | CX17: 1 | EF17: 1 | FQ17: 1
A18: SI | B18: 1 | C18: 1 | E18: 13 | F18: Corti, Guillermo Omar | H18: guillermo.corti@suseguro.com.ar | O18: X | S18: x | AN18: 1 | BW18: 1 | CS18: 1 | FQ18: 1
C19: 1 | E19: 14 | F19: Dalmau, Ignacio Daniel | G19: MAPFRE | H19: idalmau@hotmail.com | U19: 1 | AM19: 1 | BW19: 1 | CB19: 1 | CJ19: 1 | FB19: 1
B20: 1 | C20: 1 | E20: 15 | F20: ESTEVEZ OMAR | G20: RIVADAVIA | H20: omar.estevez@yahoo.com.ar | N20: X | O20: X | T20: x | Z20: 1 | AM20: 1 | CD20: 1 | CX20: 1 | EF20: 1 | FA20: 1
E21: 16 | F21: Farmache Jorge Alfredo | AM21: 1 | DG21: 1
A22: si | B22: 1 | C22: 1 | E22: 17 | F22: Felipe, Guillermo Ignacio | G22: SAN CRISTOBAL | H22: guillermofelipe820@gmail.com | S22: x | U22: 1 | Z22: 1 | CJ22: 1 | CQ22: 1 | CR22: 1 | CT22: 1 | CU22: 1 | FQ22: 1
A23: 1 | B23: 1 | C23: 1 | E23: 18 | F23: Figueroa, María Belén | G23: SMG SANCOR | H23: belenfigue@yahoo.com.ar | CD23: 2 | CX23: 1
A24: no | B24: 1 | C24: 1 | E24: 19 | F24: FREIRE ERICA | G24: MAPFRE | H24: ericafreire2004@hotmail.com | BW24: 1 | CB24: 1 | CS24: 1 | CX24: 1 | DG24: 1 | FC24: 1
A25: no atiende | C25: 1 | E25: 20 | F25: GOMEZ JULIETA | G25: SANCOR | H25: gomezjulieta914@gmail.com | O25: X | T25: x
B26: 0 | C26: 1 | E26: 21 | F26: Marón, Flavio | H26: maronflavio@hotmail.com | T26: 1 | U26: 1 | AF26: 1 | CS26: 1
A27: no | E27: 22 | F27: Martiarena Cruzado, Santiago | H27: santiago@pennesi.com.ar
A28: no | C28: 1 | E28: 23 | F28: Mazantini, Gabriel | G28: SAN CRISTOBAL | H28: gabrielmazzantini09@gmail.com | N28: X | O28: X | AQ28: 1 | BW28: 1 | BY28: 1 | DG28: 1
A29: no | C29: 1 | E29: 24 | F29: Monzón, Patricia Silvina | H29: patulino@live.com.ar | BW29: 1 | CS29: 1 | DW29: 1 | FQ29: 1
A30: si | B30: 1 | C30: 1 | E30: 25 | F30: Moresechi, Leopoldo José | H30: moreschirosso@gmail.com | BW30: 1 | CD30: 1 | CL30: 1 | CX30: 1 | DE30: 1 | DW30: 1 | EF30: 1 | FA30: 1
A31: si | B31: 1 | C31: 1 | E31: 26 | F31: Naim Mieras Janousek, Franco | H31: francomieras@gmail.com | P31: x | S31: x | Z31: 1 | BW31: 1 | CS31: 1 | CU31: 1 | CW31: 1 | CX31: 1 | DE31: 1 | DG31: 1 | EF31: 1 | FA31: 1 | FF31: 1
A32: no | C32: 1 | E32: 27 | F32: NAJURIETA SANTIAGO | H32: i.pas.najurieta@gmail.com | N32: X | S32: x | Z32: 1 | BW32: 1 | BY32: 2 | CD32: 1 | CL32: 1
A33: ? | B33: 1 | C33: 1 | E33: 28 | F33: Ospitaletche, Néstor Javier | H33: nestorjavierospitaletche@gmail.com | O33: X | S33: x | Z33: 1 | AF33: 1 | BW33: 1 | EF33: 1 | FB33: 1 | FH33: 1 | FI33: 1 | FJ33: 1
A34: si | B34: 1 | C34: 1 | E34: 29 | F34: Paso, Gonzalo Javier | H34: gonzalopaso@hotmail.com | N34: x | O34: x | R34: xx | AF34: 1 | BW34: 1 | BX34: 1 | CD34: 1 | CV34: 1 | DG34: 1 | DP34: 1 | FJ34: 1
E35: 30 | F35: PENNESI JORGE MAURICIO | DW35: 1 | FR35: 1
C36: 1 | E36: 31 | F36: Perello Juan P | CV36: 1
A37: si x 2 | B37: 2 | C37: 1 | E37: 32 | F37: Ponce Vaccarino Rodrigo | H37: orgvaccarino@yahoo.com.ar | N37: X | O37: X | U37: 1 | Z37: 1 | AF37: 1 | BW37: 1 | BY37: 1 | CK37: 1 | CV37: 1 | DE37: 1 | EC37: 1 | FA37: 1 | FB37: 1 | FF37: 1
C38: 1 | E38: 33 | F38: Shelia, Vanesa Preece | H38: info@estevezseguros.com.ar | N38: X | BY38: 1 | CJ38: 1 | CL38: 1 | CX38: 1 | CZ38: 1 | DG38: 1 | FR38: 1
E39: 34 | F39: SORIA JULIETA MACARENA | H39: julimaca25@gmail.com | CV39: 1 | CX39: 1
A40: 1 | B40: 1 | C40: 1 | E40: 35 | F40: Sosa Moreno, Gastón Alejandro | H40: sosamorenogaston@gmail.com | BW40: 1 | BX40: 1 | BY40: 1 | EF40: 1 | FB40: 1
E41: 36 | F41: SPANO CLAUDIO JOSE | H41: claudio@pennesi.com.ar | CX41: 1 | DE41: 1 | DG41: 1
...

Sheet OBJETIVOS COMERCIALES
B2: OBJETIVOS COMERCIALES
B4: 1 | C4: VISITA EN EL MES A CADA UNO DE LOS PAS DE LA ORGANIZACIÓN
C5: BUSCAR PRODUCTIVIDAD EN CADA PAS
C6: EVALUAR ESTADO ACTUAL CON LA ORGANIZACIÓN
C7: POTENCIAR CON CAMPAÑAS COMERCIALES
C8: INCREMENTAR LA CARTERA DE CADA PAS
B10: 2 | C10: CAPTACION DE NUEVOS PAS
C11: BUSCAR CAPTAR PAS CON CARTERA
C12: ARMAR LISTADO DE CANDIDATOS VISTOS
C13: DESARROLLAR ACCIONES PARA CAPTAR
C14: REVISAR CARTERAS QUE NO ESTEN DEBAJO DE LA ORG - PARA VINCULAR
B16: 3 | C16: ACCIONES MENSUALES PROPUESTAS
C17: CAPACITACIONES
C18: DESAYUNO DE TRABAJO
C19: COMUNICACIÓN // INFORMACION
C20: ALMUERZO // CENA
C21: ARTICULO PROMOCIONAL PARA EL PAS DE MAYOR PRODUCCION O COMPROMISO

Sheet BASE DATOS PAS
B2: LLAMADO TELEFONICO | C2: 1
B3: REUNION PRESENCIAL | C3: 2
B4: No laboral
H5: ABRIL | K5: MAYO | AP5: JUNIO | BU5: JULIO | CZ5: AGOSTO | ED5: SETIEMBRE
A6: N° | B6: Nombre Productor | C6: Compañía | D6: VERDE | E6: ROJO | F6: AMARILLO | G6: Correos Electrónicos | H6: 28 | I6: 29 | J6: 30 | K6: 1 | L6: 2 | M6: 3 | N6: 4 | O6: 5 | P6: 6 | Q6: 7 | R6: 8 | S6: 9 | T6: 10 | U6: 11 | V6: 12 | W6: 13 | X6: 14 | Y6: 15 | Z6: 16 | AA6: 17 | AB6: 18 | AC6: 19 | AD6: 20 | AE6: 21 | AF6: 22 | AG6: 23 | AH6: 24 | AI6: 25 | AJ6: 26 | AK6: 27 | AL6: 28 | AM6: 29 | AN6: 30 | AO6: 31 | AP6: 1 | AQ6: 2 | AR6: 3 | AS6: 4 | AT6: 5 | AU6: 6 | AV6: 7 | AW6: 8 | AX6: 9 | AY6: 10 | AZ6: 11 | BA6: 12 | BB6: 13 | BC6: 14 | BD6: 15 | BE6: 16 | BF6: 17 | BG6: 18 | BH6: 19 | BI6: 20 | BJ6: 21 | BK6: 22 | BL6: 23 | BM6: 24 | BN6: 25 | BO6: 26 | BP6: 27 | BQ6: 28 | BR6: 29 | BT6: 30 | BU6: 1 | BV6: 2 | BW6: 3 | BX6: 4 | BY6: 5 | BZ6: 6 | CA6: 7 | CB6: 8 | CC6: 9 | CD6: 10 | CE6: 11 | CF6: 12 | CG6: 13 | CH6: 14 | CI6: 15 | CJ6: 16 | CK6: 17 | CL6: 18 | CM6: 19 | CN6: 20 | CO6: 21 | CP6: 22 | CQ6: 23 | CR6: 24 | CS6: 25 | CT6: 26 | CU6: 27 | CV6: 28 | CW6: 29 | CX6: 30 | CY6: 31 | CZ6: 1 | DA6: 2 | DB6: 3 | DC6: 4 | DD6: 5 | DE6: 6 | DF6: 7 | DG6: 8 | DH6: 9 | DI6: 10 | DJ6: 11 | DK6: 12 | DL6: 13 | DM6: 14 | DN6: 15 | DO6: 16 | DP6: 17 | DQ6: 18 | DR6: 19 | DS6: 20 | DT6: 21 | DU6: 22 | DV6: 23 | DW6: 24 | DX6: 25 | DY6: 26 | DZ6: 27 | EA6: 28 | EB6: 29 | EC6: 30 | ED6: 1 | EE6: 2 | EF6: 3 | EG6: 4 | EH6: 5 | EI6: 6 | EJ6: 7 | EK6: 8 | EL6: 9 | EM6: 10 | EN6: 11 | EO6: 12 | EP6: 13 | EQ6: 14 | ER6: 15 | ES6: 16 | ET6: 17 | EU6: 18 | EV6: 19 | EW6: 20 | EX6: 21 | EY6: 22 | EZ6: 23 | FA6: 24 | FB6: 25 | FC6: 26 | FD6: 27 | FE6: 28 | FF6: 29 | FG6: 30 | FH6: 31
A7: 1 | B7: Agrelo, Gonzalo | C7: SANCOR | F7: 1 | G7: gagrelo@pennesi.com.ar | R7: 2 | AF7: 1 | AM7: 1 | AX7: 1
A8: 2 | B8: Aguirre, Mauricio | C8: MAPFRE | D8: 1 | G8: segurosaguirre@hotmail.com | H8: 2 | AL8: 1 | AQ8: 1 | AS8: 2 | BF8: 1 | CA8: 1
A9: 3 | B9: Alcaniz, Angel David | C9: SMG | F9: 1 | G9: daalcanis@gmail.com | AK9: 1 | BN9: 1
A10: 4 | B10: Antún, Maria Elena | E10: 1 | G10: mariaelena64@live.com.ar | BF10: 2 | CD10: 2
A11: 5 | B11: Barbero, María Fernanda | C11: SAN CRISTOBAL | D11: 1 | G11: infodos.jcorg@gmail.com | H11: 1 | I11: 1 | J11: 1 | AS11: 1 | BB11: 1 | BH11: 1 | BT11: 1 | CA11: 1
A12: 6 | B12: BARDON MARIA INES | D12: 1 | G12: mariainesbardon@gmail.com | O12: 1 | S12: 2 | V12: 1 | AN12: 1 | AU12: 1 | BB12: 1 | BH12: 2 | BU12: 1 | CD12: 1
A13: 7 | B13: BARRERA JOSE LUIS | C13: MAPFRE | D13: 1 | G13: barrera_joseluis@yahoo.com | P13: 2 | AL13: 1 | AQ13: 2
A14: 8 | B14: Bassanese, Virginia | D14: 0 | G14: vbassanese@jcorg.com.ar | BA14: 1
A15: 9 | B15: Ale Bergas | C15: SMG RIVADAVIA | D15: 1 | G15: alejandrobergas@gmail.com | H15: 1 | I15: 2 | J15: 1 | AQ15: 1 | AZ15: 2 | BL15: 1
A16: 10 | B16: Bustos López, David Renato | E16: 1 | G16: davidrenatobustos@hotmail.com | BO16: 1
A17: 11 | B17: CAPITANI HORACIO ANIBAL | C17: SAN CRISTOBAL | D17: 1 | G17: hcapitani16@gmail.com | H17: 1 | I17: 1 | J17: 2 | AE17: 1 | AN17: 1 | AX17: 2 | BF17: 2 | BP17: 2 | CD17: 1
A18: 12 | B18: Chiarolla, María Cecilia | C18: SANCOR | F18: 1 | G18: cecichiarolla@hotmail.com | AS18: 1 | BB18: 1 | BU18: 1
A19: 13 | B19: Corti, Guillermo Omar | D19: 1 | G19: guillermo.corti@suseguro.com.ar | AE19: 1 | AL19: 1 | BH19: 1 | BL19: 1 | CE19: 1
A20: 14 | B20: Dalmau, Ignacio Daniel / Omar | C20: MAPFRE | D20: 1 | G20: idalmau@hotmail.com | Q20: 2 | BP20: 1
A21: 15 | B21: ESTEVEZ OMAR | C21: RIVADAVIA | D21: 1 | G21: omar.estevez@yahoo.com.ar | S21: 2 | V21: 1 | AF21: 1 | AZ21: 1 | BL21: 1 | CD21: 1
A22: 17 | B22: Felipe, Guillermo Ignacio | C22: SAN CRISTOBAL | D22: 1 | G22: guillermofelipe820@gmail.com | AJ22: 1 | AN22: 1 | BB22: 1 | BM22: 2 | CB22: 1
A23: 18 | B23: Figueroa, María Belén | C23: SMG SANCOR | D23: 0 | G23: belenfigue@yahoo.com.ar | V23: 1 | AN23: 1
A24: 19 | B24: FREIRE ERICA | C24: MAPFRE | F24: 1 | G24: ericafreire2004@hotmail.com | AK24: 1 | AT24: 1 | BM24: 1
A25: 20 | B25: GOMEZ JULIETA | C25: SANCOR | E25: 1 | G25: gomezjulieta914@gmail.com | AX25: 1 | BO25: 1
A26: 21 | B26: Marón, Flavio | F26: 1 | G26: maronflavio@hotmail.com
A27: 22 | B27: Martiarena Cruzado, Santiago | F27: 1 | G27: santiago@pennesi.com.ar | AX27: 1
A28: 23 | B28: Mazantini, Gabriel | C28: SAN CRISTOBAL | E28: 1 | G28: gabrielmazzantini09@gmail.com | R28: 1 | BM28: 1
A29: 24 | B29: Monzón, Patricia Silvina | D29: 0 | G29: patulino@live.com.ar | R29: 2 | V29: 1 | AF29: 1 | BA29: 1
A30: 25 | B30: Moresechi, Leopoldo José | D30: 1 | G30: moreschirosso@gmail.com | P30: 1 | AE30: 1 | AN30: 1 | AS30: 1 | AY30: 2 | BG30: 1 | BL30: 1
A31: 26 | B31: Naim Mieras Janousek, Franco | D31: 1 | G31: francomieras@gmail.com | H31: 2 | BA31: 1 | BH31: 1 | BO31: 1 | BT31: 1
A32: 27 | B32: NAJURIETA SANTIAGO | D32: 0 | G32: i.pas.najurieta@gmail.com | H32: 2 | I32: 1 | Y32: 1 | AG32: 1 | AN32: 1 | AZ32: 1 | BN32: 1 | BU32: 1 | CB32: 1 | CE32: 2
A33: 28 | B33: Ospitaletche, Néstor Javier | D33: 1 | G33: nestorjavierospitaletche@gmail.com | I33: 2 | J33: 1 | R33: 1 | V33: 2 | AM33: 1 | BG33: 1 | CE33: 1
A34: 29 | B34: Paso, Gonzalo Javier | D34: 1 | G34: gonzalopaso@hotmail.com | I34: 2 | AJ34: 1 | AK34: 2 | BA34: 1 | BT34: 1 | CA34: 1
A35: 30 | B35: Perello Juan P | E35: 1
A36: 31 | B36: Ponce Vaccarino Rodrigo | D36: 1 | G36: orgvaccarino@yahoo.com.ar | Q36: 1 | AM36: x | AZ36: 1 | CB36: 1
A37: 32 | B37: Sergio Estevez /Shelia, Vanesa Preece | D37: 1 | G37: info@estevezseguros.com.ar | H37: 2 | V37: 1 | AJ37: 1 | AT37: 1 | AY37: 2 | BF37: 1 | BL37: 2
A38: 33 | B38: SORIA JULIETA MACARENA | E38: 1 | G38: julimaca25@gmail.com | AX38: 1 | BO38: 1
A39: 34 | B39: Sosa Moreno, Gastón Alejandro | D39: 1 | G39: sosamorenogaston@gmail.com | I39: 1 | R39: 1 | AS39: 1 | AZ39: 1
A40: 35 | B40: SPANO CLAUDIO JOSE | F40: 1 | G40: claudio@pennesi.com.ar | BO40: 1 | BT40: 1
A41: 36 | B41: Toro, Érica | D41: 1 | G41: ericatorog@hotmail.com | H41: 2 | AJ41: 1 | AS41: 2 | BA41: 1 | BH41: 1
...

Sheet Hoja6
A3: Etiquetas de fila | B3: Suma de LLAMADOS | C3: Suma de OBJETIVO LLAMADOS | D3: Suma de ENTREVISTAS | E3: Suma de OBJETIVO ENTREVISTAS
A4: ABRIL | B4: 17 | C4: 58 | D4: 12 | E4: 26
A5: MAYO | B5: 55 | C5: 58 | D5: 17 | E5: 26
A6: JUNIO | B6: 83 | C6: 58 | D6: 22 | E6: 26
A7: JULIO | B7: 22 | C7: 58 | D7: 3 | E7: 26
A8: Total general | B8: 177 | C8: 232 | D8: 54 | E8: 104
A19: Suma de AMARILLO | B19: Suma de ROJO | C19: Suma de VERDE | D19: Cuenta de Nombre Productor
A20: 9 | B20: 9 | C20: 26 | D20: 57

Sheet RESUMEN
F6: MESES | G6: LLAMADOS | H6: PROM/SEM | I6: OBJETIVO LLAMADOS | J6: ENTREVISTAS | K6: PROM/SEM | L6: OBJETIVO ENTREVISTAS
F7: ABRIL | G7: 17 | H7: 4.25 | I7: ='BASE DATOS PAS'!$A$63 -> 58 | J7: 12 | K7: 3 | L7: ='BASE DATOS PAS'!$D$64 -> 26
F8: MAYO | G8: 55 | H8: 13.75 | I8: ='BASE DATOS PAS'!$A$63 -> 58 | J8: 17 | K8: 4.25 | L8: ='BASE DATOS PAS'!$D$64 -> 26
F9: JUNIO | G9: 83 | H9: 20.75 | I9: ='BASE DATOS PAS'!$A$63 -> 58 | J9: 22 | K9: 5.5 | L9: ='BASE DATOS PAS'!$D$64 -> 26
F10: JULIO | G10: 22 | H10: 5.5 | I10: ='BASE DATOS PAS'!$A$63 -> 58 | J10: ='BASE DATOS PAS'!F74 -> 3 | K10: 0.75 | L10: ='BASE DATOS PAS'!$D$64 -> 26
E18: N° | F18: Nombre Productor | G18: Compañía | H18: VERDE | I18: ROJO | J18: AMARILLO
E19: 1 | F19: Agrelo, Gonzalo | G19: SANCOR | J19: 1
E20: 2 | F20: Aguirre, Mauricio | G20: MAPFRE | H20: 1
E21: 3 | F21: Alcaniz, Angel David | G21: SMG | J21: 1
E22: 4 | F22: Antún, Maria Elena | I22: 1
E23: 5 | F23: Barbero, María Fernanda | G23: SAN CRISTOBAL | H23: 1
E24: 6 | F24: BARDON MARIA INES | H24: 1
E25: 7 | F25: BARRERA JOSE LUIS | G25: MAPFRE | H25: 1
E26: 8 | F26: Bassanese, Virginia | H26: 0
E27: 9 | F27: Ale Bergas | G27: SMG RIVADAVIA | H27: 1
E28: 10 | F28: Bustos López, David Renato | I28: 1
E29: 11 | F29: CAPITANI HORACIO ANIBAL | G29: SAN CRISTOBAL | H29: 1
E30: 12 | F30: Chiarolla, María Cecilia | G30: SANCOR | J30: 1
E31: 13 | F31: Corti, Guillermo Omar | H31: 1
E32: 14 | F32: Dalmau, Ignacio Daniel / Omar | G32: MAPFRE | H32: 1
E33: 15 | F33: ESTEVEZ OMAR | G33: RIVADAVIA | H33: 1
E34: 17 | F34: Felipe, Guillermo Ignacio | G34: SAN CRISTOBAL | H34: 1
E35: 18 | F35: Figueroa, María Belén | G35: SMG SANCOR | H35: 0
E36: 19 | F36: FREIRE ERICA | G36: MAPFRE | J36: 1
E37: 20 | F37: GOMEZ JULIETA | G37: SANCOR | I37: 1
E38: 21 | F38: Marón, Flavio | J38: 1
E39: 22 | F39: Martiarena Cruzado, Santiago | J39: 1
E40: 23 | F40: Mazantini, Gabriel | G40: SAN CRISTOBAL | I40: 1
E41: 24 | F41: Monzón, Patricia Silvina | H41: 0
E42: 25 | F42: Moresechi, Leopoldo José | H42: 1
E43: 26 | F43: Naim Mieras Janousek, Franco | H43: 1
E44: 27 | F44: NAJURIETA SANTIAGO | H44: 0
E45: 28 | F45: Ospitaletche, Néstor Javier | H45: 1
E46: 29 | F46: Paso, Gonzalo Javier | H46: 1
E47: 30 | F47: Perello Juan P | I47: 1
E48: 31 | F48: Ponce Vaccarino Rodrigo | H48: 1
E49: 32 | F49: Sergio Estevez /Shelia, Vanesa Preece | H49: 1
E50: 33 | F50: SORIA JULIETA MACARENA | I50: 1
E51: 34 | F51: Sosa Moreno, Gastón Alejandro | H51: 1
E52: 35 | F52: SPANO CLAUDIO JOSE | J52: 1
...

Sheet TEMAS GESTIONES
B5: TEMAS A GESTIONAR
B7: PAS | C7: TEMA
C8: REVISION COMISIONES PENDIENTES PAS PARA LIQUIDAR EN SMG Y OTRAS CIAS
C9: CAPACITACION DE RETIRO SAN CRISTOBAL
C10: ALTAS PENDIENTES
C11: PREVENCION SALUD
C12: VISITA A SMG PAS NUEVOS
C13: REUNION Y VISITA A MAPFRE
C14: ORDENAR LAS ALTAS PENDIENTES O VINCULACIONES DE LOS PAS PARA TENER UN RESUMEN
C15: COORDINAR REUNION CON RETIRO SANCOR - (REF JUAN PABLO AQUILA PERO SE PUEDEN SUMAR MAS)
C16: ARMAR COMPARATIVO DE PRODUCTOS Y COMISIONES DE RETIRO (SAN CRISTOBAL Y SANCOR)

Sheet ALTAS CIAS
J1: SEGUROS GENERALES | R1: ESTADO ACTUAL DE ART BAJO LA ORGANIZACIÓN | Z1: CARTERA FUERA DE LA ORG
A2: N° | B2: Nombre Productor | D2: ESTADO PAS | E2: POTENCIALIDAD | F2: TOTAL | G2: BAJA | H2: SIN POTENCIAL | I2: ESTADO | J2: S CRISTOBAL | K2: SANCOR | L2: SMG | M2: MAPFRE | N2: BERKLEY | O2: ZURICH | P2: RIVADAVIA | Q2: MERCANTIL | R2: ASOCIART | S2: PREVENCION | T2: SMG ART | U2: PROVINCIA | V2: ANDINA | W2: GALENO
A3: 1 | B3: Agrelo, Gonzalo | D3: ACTIVO | E3: NO | F3: 1 | H3: 1 | J3: SI | Z3: SANCOR
A4: 2 | B4: Aguirre, Mauricio | C4: AVISADO | D4: ACTIVO | E4: SI | F4: 1 | I4: REVISAR | J4: SI | L4: SI | M4: SI | P4: SI | Z4: FEDERACION - (REVISAR)
A5: 3 | B5: Alcaniz, Angel David | D5: ACTIVO | E5: SI | F5: 1 | I5: REVISAR | J5: SI
A6: 4 | B6: Ale Bergas | D6: ACTIVO | E6: SI | F6: 1 | J6: SI | L6: SI | P6: SI | Q6: SI | Z6: SI - EN OTRA CIA
A7: 5 | B7: Antún, Maria Elena | D7: ACTIVO | E7: NO | F7: 1 | H7: 1 | I7: REVISAR | J7: SI
A8: 6 | B8: ARROYO YASMIN | E8: SI | F8: 1 | K8: SI | L8: SI | Z8: REVISAR
A9: 7 | B9: Barbero, María Fernanda | D9: ACTIVO | E9: SI | F9: 1 | J9: SI | K9: NO TIENEN CODIGO | L9: SI | Q9: SI
A10: 8 | B10: BARDON MARIA INES | D10: ACTIVO | E10: SI | F10: 1 | J10: SI | L10: SI | P10: SI | Q10: SI
A11: 9 | B11: BARRERA JOSE LUIS | C11: AVISADO | D11: ACTIVO | E11: SI | F11: 1 | J11: SI | K11: NO TIENEN CODIGO | L11: SI | M11: SI | N11: SI | Z11: FEDERACION
A12: 10 | B12: Bassanese, Virginia | D12: ACTIVO | E12: SI | F12: 1 | J12: SI | K12: SI | L12: SI | M12: SI | P12: SI
A13: 11 | B13: Bustos López, David Renato | D13: BAJA | F13: 1 | G13: 1
A14: 12 | B14: CAPITANI HORACIO ANIBAL | D14: ACTIVO | E14: SI | F14: 1 | L14: SI | M14: SI | N14: SI | P14: SI | Z14: SAN CRISTOBAL - LA SEGUNDA - EXPERTA - RIO URUGUAY
A15: 13 | B15: CHACOMA GUSTAVO | E15: SI | F15: 1 | J15: SI | K15: SI
A16: 14 | B16: Chiarolla, María Cecilia | E16: NO | F16: 1 | H16: 1 | J16: SI
A17: 15 | B17: Corti, Guillermo Omar | E17: SI | F17: 1 | J17: SI | K17: SI | M17: SI | Z17: REVISAR
A18: 16 | B18: Dalmau, Ignacio Daniel | E18: SI | F18: 1 | J18: SI | L18: SI | Z18: LA SEGUNDA - REVISAR
A19: 17 | B19: ESTEVEZ OMAR | E19: SI | F19: 1 | L19: SI | P19: SI | Q19: SI | Z19: REVISAR
A20: 18 | B20: Farmache Jorge Alfredo | D20: BAJA | F20: 1 | G20: 1
A21: 19 | B21: Federico Lucato | E21: SI | F21: 1 | L21: SI | Q21: SI | Z21: SANCOR - RIO URUGUAY
A22: 20 | B22: Felipe, Guillermo Ignacio | E22: SI | F22: 1 | J22: SI | Q22: SI | Z22: REVISAR
A23: 21 | B23: Figueroa, María Belén | E23: NO | F23: 1 | H23: 1 | K23: SI | L23: SI | Z23: REVISAR
A24: 22 | B24: FREIRE ERICA | E24: SI | F24: 1 | J24: SI | P24: SI | Z24: REVISAR
A25: 23 | B25: GOMEZ JULIETA | E25: NO | F25: 1 | H25: 1 | K25: SI | Z25: REVISAR - FEDERACION Y LA SEGUNDA
A26: 24 | B26: JAVIER ALTAMIRANO | F26: 1 | J26: PRESENTADO | L26: PRESENTADO | Q26: PRESENTADO
A27: 25 | B27: LA CIVITA JOSE | E27: SI | F27: 1 | K27: SI | L27: SI | Z27: NO TENE CARTERA
A28: 26 | B28: LARIO VANESA (FER CARMENO) | F28: 1 | J28: PRESENTADO | L28: PRESENTADO | Q28: PRESENTADO
A29: 27 | B29: Marón, Flavio | E29: NO | F29: 1 | H29: 1 | J29: SI | Z29: REVISAR
A30: 28 | B30: Martiarena Cruzado, Santiago | D30: BAJA | F30: 1 | G30: 1
A31: 29 | B31: Mazantini, Gabriel | E31: NO | F31: 1 | H31: 1 | J31: SI | P31: SI | Z31: REVISAR
A32: 30 | B32: Monzón, Patricia Silvina | F32: 1 | Z32: REVISAR
A33: 31 | B33: Moran Fernando | E33: SI | F33: 1 | Z33: MERCANTIL - BERKLEY - MERIDIONAL -
A34: 32 | B34: Moresechi, Leopoldo José | E34: SI | F34: 1 | J34: SI | K34: SI | N34: SI | P34: SI
A35: 33 | B35: Naim Mieras Janousek, Franco | C35: AVISADO | E35: SI | F35: 1 | J35: SI | K35: SI | L35: SI | Z35: TRIUNFO - REVISAR
A36: 34 | B36: NAJURIETA SANTIAGO | D36: BAJA | E36: NO | F36: 1 | G36: 1
A37: 35 | B37: Navarro Javier | E37: SI | F37: 1 | K37: SI | L37: SI | N37: SI | Z37: REVISAR
A38: 36 | B38: OROPEL BRUNO | E38: NO | F38: 1 | H38: 1 | K38: SI | Z38: NO TENE CARTERA
A39: 37 | B39: Orozco Marita | E39: SI | F39: 1 | K39: SI | L39: SI | Z39: NO TENE CARTERA
A40: 38 | B40: Ospitaletche, Néstor Javier | E40: SI | F40: 1 | J40: SI | Z40: SANCOR - REVISAR
...

Sheet BASE DATOS NUEVOS PAS
B3: LISTADO DE PAS NUEVOS PARA VINCULAR
B6: N° | C6: Nombre Productor | D6: CANDIDATOS CON INTERES | E6: Compañía | F6: Correos Electrónicos
B7: 1 | C7: ALEXIS SIVENT | E7: BERKLEY , MERCANTIL , RIVADAVIA
B8: 2 | C8: SOLE YAÑEZ | E8: MERCANTIL , BKL ,
B9: 3 | C9: DUILIO SANTORO | E9: VARIAS
B10: 4 | C10: MARCELO CALVERMATTEN | E10: MERCANTIL , BKL , SANCOR ,
B11: 5 | C11: GUSTAVO MENDOZA | E11: VARIAS
B12: 6 | C12: ANY RODRIGUEZ HNA COLO MERCANTIL) | E12: FEDERACION , MERCANTIL
B13: 7 | C13: MONTALTO PABLO | E13: TRIUNFO
B14: 8 | C14: LOZA JORGE | E14: SANCOR , MERIDIONAL , BKL
B15: 9 | C15: DAVID PONCE (HERMANO DE RODRIGO) | E15: SANCOR , MERIDIONAL , BKL , MERC.
B16: 10 | C16: BUTTANI ALEJANDRO | E16: MERCANTI, BKL , SANCOR
B17: 11 | C17: MARCELO MARTINEZ | E17: ALLIANZ
B18: 12 | C18: EDU SERRA | E18: MERCANTIL , BKL
... B20: 14 | C20: ALEJANDRO STORELLI | E20: MERCANTIL
B21: 15 | C21: MAXIMILIANO PETTIGNANO | E21: NUEVO | F21: pettignanopas@gmail.com
B22: 16 | C22: MENDOZA GUSTAVO
B23: 17 | C23: ANDRES MANZANO
B24: 18 | C24: ANTONELLA MARIN
B25: 19 | C25: GABRIELA ESPINOZA | E25: PAS NUEVA SOLO RIO URUGUAY | F25: RIVADAVIA
B26: 20 | C26: Cynthia Rios | E26: pas nueva contacto de Rivadavia Seguros | F26: RIVADAVIA
B27: 21 | C27: Luz Molinaro | E27: PAS Ayudante de Alexis
B28: 22 | C28: Eduardo Lopez | E28: siniestros de triunfo
B29: 23 | C29: LAURA BAEZA | D29: 1 | E29: OK CURSO
B30: 24 | C30: JOSE LACIVITA | D30: 1 | E30: OK CURSO
B31: 25 | C31: GABRIELA LAGOS | E31: REF FLOR -no tiene la matricula-le llega- | F31: 2615669905
B32: 26 | C32: VALE CALERI (Prima de Franco Mieras) | E32: REF FRANCO | F32: 2616566807
B33: 27 | C33: AGUSTINA LUQUE | D33: 1 | E33: REF FRANCO | F33: 2613737702
B34: 28 | C34: LUCIANA HERRERO | E34: REF FRANCO | F34: 2613396352
B35: 29 | C35: PABLO PEREZ (TURCO) | E35: REF FLOR (DE PARTE DE FLOR) QUEDAMOS EN UN CAFÉ | F35: 2612405015
B36: 30 | C36: GENARO BELLO | E36: tiene organización Unum , nos vamos a juntar | F36: 2615439622
B37: 31 | C37: DELIA BARROSO (SANTA ROSA) | D37: 1 | E37: CONTACTO DE AGRELO , EN SANCOR , SE COPO VIRNR VIERNES | F37: 2613607901
B38: 32 | C38: CLAUDIO OLGUIN | F38: 2612412989
B39: 33 | C39: JOSE ARAUJO | E39: INE BARDON Pas MENDOZA BROKER | F39: 2613024690 /2612029233
B40: 34 | C40: MARTINA ZALAZAR | E40: ESTA CON HERVIDA PAAS NUEVA | F40: ESTEFI ZAMARIAN
B41: 35 | C41: ROMINA PONCE | E41: FLOR CONTACTO (SAN MARTIN SUR OF) | F41: 2615341933
B42: 36 | C42: YASMIN | D42: 1 | E42: GRUPO WAS PRODUCTORES viene hoy 15 30
B43: 37 | C43: LUZ DELLAFIORE | E43: PAS NUEVA LLAMAR 14:30 HS | F43: 2613044170
B44: 38 | C44: VERONICA CORVALAN | D44: 1 | E44: PAS NUEVO HA SIDO MAMA HECE POCO ESTAMOS EN CONTACTO | F44: 2615552698
B45: 39 | C45: SARA ESTA EN UN BROKER NO ME DIO MAS DATOS | E45: PAS NUEVO NO ESTA INTERESADA | F45: 2613628496
...

Sheet EJECUTIVOS COM
B4: COMPAÑÍA | C4: EJECUTIVO
B5: MAPFRE | C5: NICOLAS PUGLISI
B6: MERCANTIL | C6: ALE TAPIA
B7: SMG | C7: IVANA SANCHEZ
B8: SANCOR | C8: ALEJANDRO DAVID
B9: ZURICH | C9: LIA CAROLINA PEREZ
B10: BERKLEY | C10: LEANDRO TARQUI
B11: ANDINA ART | C11: ERICA LOPEZ
B12: PREVENCION ART
B13: SAN CRISTOBAL | C13: ALE SANTINI
B14: RIVADAVIA | C14: GABRIEL VALDIVIESO
B15: GALENO | C15: FLORENCIA TEURLAY

Sheet CANDIDATOS Y HORARIO
A1: CANT. | B1: Productor | C1: DNI | D1: MATRICULA | E1: telefono | G1: confirmacion | H1: ASIST PRESENTACION | I1: NUEVA REUNION | J1: REUNIONES INDIVIDUALES | K1: CONFIRMACION DEFINITIVA | L1: DOC ALTA SANCOR | M1: DISPONIBILIDAD HORARIIO | N1: DIAS DE CURSOS
A2: 1 | B2: GUTIERRES MAURICIO | C2: 34756360 | D2: 105253 | E2: 2615956841 | F2: mgpasseguros@gmail.com | G2: OK | H2: 1 | M2: NO HAY PROBLEMA | N2: LUNES Y MIERCOLES
A3: 2 | B3: LA CIVITA JOSE | C3: 27300314 | D3: 102287 | E3: 2614683627 | F3: joselacivita@gmail.com | G3: OK | H3: 1 | M3: DESPUES DE 14HS | N3: LUNES Y MIERCOLES
A4: 3 | B4: BAEZA LAURA | E4: 2616551259 | G4: OK | I4: 1
A5: 4 | B5: NAJURIETA SANTIAGO | C5: 22407246 | D5: 93020 | E5: 2615595394 | F5: santiago.najurieta@sobrecasas.com | G5: OK | H5: 1 | M5: DESPUES DE 16HS | N5: LUNES Y MIERCOLES
A6: 5 | B6: OROPEL BRUNO | C6: 30099770 | D6: 104953 | E6: 2614371774 - 2613019140 | F6: oropelbruno@gmail.com | G6: ok | H6: 1 | M6: NO HAY PROBLEMA | N6: LUNES Y MIERCOLES
A7: 6 | B7: COHEN NOCERA GIMENA | E7: 2613130017 | G7: ok | I7: 1
A8: 7 | B8: TORRES MARIELA | E8: 2616067235 | G8: ok
A9: 8 | B9: BUSTOS DAMIAN | I9: 1
A10: 9 | B10: MARINA REY | E10: 2617498600 | I10: 1
A11: 10 | B11: YASMIN ARROYO | C11: 36030776 | D11: 103049 | E11: 2614715545 | F11: arroyoyasmin.seguros@gmail.com | G11: OK | H11: 1 | M11: DESPUES 15HS | N11: LUNES Y MIERCOLES
A12: 11 | B12: DELIA BARROSO | E12: 2613607901 | G12: no sabe si viene
A13: 12 | B13: CORVALAN VERONICA | C13: 37966891 | D13: 103913 | E13: 2615552698 | F13: veronicacorvalan@live.com.ar | G13: OK | H13: 1 | M13: TARDE | N13: LUNES Y MIERCOLES
A14: 13 | B14: AGÜERO LUIS | E14: 2612597459 | G14: ?
A15: 14 | B15: PETIGNIANO MAXIMILIANO | C15: 28464431 | D15: 91004 | E15: 2616631812 | F15: pettignanopas@gmail | G15: OK | H15: 1 | M15: NO HAY PROBLEMA | N15: LUNES Y MIERCOLES
A16: 15 | B16: MATOS MARIANA | E16: 2616367817 | G16: OK | I16: 1
A17: 16 | B17: Cynthia Sorli | E17: 2616409291 | G17: ok
A18: 17 | B18: ismael | H18: =SUM(H2:H17) -> 7 | I18: =SUM(I2:I17) -> 5
A19: 18 | B19: Danilo Conil
B22: vero corvalan
B23: ismael
B24: danilo conil
B25: laura baeza
B26: jose lacivita
B27: yasmin arroyo
B28: bruno oropel
B29: mauricio gutierrez ??
B30: santiago najurieta

Sheet BASE DATOS PROGRAMA NUEVO PAS
B4: PROGRAMA NUEVOS PAS
B7: N° | C7: Nombre Productor | D7: Compañía | E7: Correos Electrónicos
B8: 1 | C8: LA CIVITA
B9: 2 | C9: LINARES SANTIAGO (EX PRUDENCIA)
B10: 3 | C10: Luz sirvent | D10: tiene grupo de pas.-
B11: 4 | C11: LAURA BAEZA
B12: 5 | C12: ESPINOZA GABRIELA
B13: 6
B14: 7
B15: 8
B16: 9
B17: 10
B18: 11
B19: 12
B20: 13
B21: 14
B22: 15
